<?xml version="1.0" encoding="utf-8"?>
<!-- This URDF was automatically created by SolidWorks to URDF Exporter! Originally created by Stephen Brawner (brawner@gmail.com) 
     Commit Version: 1.5.1-0-g916b5db  Build Version: 1.5.7152.31018
     For more information, please see http://wiki.ros.org/sw_urdf_exporter -->
<robot
  name="sunday_description">
  <link
    name="base_link">
    <inertial>
      <origin
        xyz="-0.0041595 -0.019776 0.12"
        rpy="0 0 0" />
      <mass
        value="0.76559" />
      <inertia
        ixx="0.0010468"
        ixy="-3.1045E-20"
        ixz="8.2718E-22"
        iyy="0.0016442"
        iyz="6.2283E-18"
        izz="0.0010468" />
    </inertial>
    <visual>
      <origin
        xyz="0 0 0"
        rpy="0 0 0" />
      <geometry>
        <mesh
          filename="package://sunday_description/meshes/base_link.STL" />
      </geometry>
      <material
        name="">
        <color
          rgba="0.62745 0.62745 0.62745 1" />
      </material>
    </visual>
    <collision>
      <origin
        xyz="0 0 0"
        rpy="0 0 0" />
      <geometry>
        <mesh
          filename="package://sunday_description/meshes/base_link.STL" />
      </geometry>
    </collision>
  </link>
  <link
    name="link_1">
    <inertial>
      <origin
        xyz="4.4076E-07 0.0088489 0.03981"
        rpy="0 0 0" />
      <mass
        value="0.46337" />
      <inertia
        ixx="0.000358"
        ixy="-8.3345E-09"
        ixz="-1.4634E-08"
        iyy="0.00035762"
        iyz="-5.6927E-05"
        izz="0.00039427" />
    </inertial>
    <visual>
      <origin
        xyz="0 0 0"
        rpy="0 0 0" />
      <geometry>
        <mesh
          filename="package://sunday_description/meshes/link_1.STL" />
      </geometry>
      <material
        name="">
        <color
          rgba="0.79216 0.81961 0.93333 1" />
      </material>
    </visual>
    <collision>
      <origin
        xyz="0 0 0"
        rpy="0 0 0" />
      <geometry>
        <mesh
          filename="package://sunday_description/meshes/link_1.STL" />
      </geometry>
    </collision>
  </link>
  <joint
    name="joint_1"
    type="revolute">
    <origin
      xyz="-0.0041595 -0.12 0.026051"
      rpy="0 0 -1.5708" />
    <parent
      link="base_link" />
    <child
      link="link_1" />
    <axis
      xyz="0 0 1" />
    <limit
      lower="-2.79"
      upper="2.79"
      effort="30"
      velocity="3.14" />
  </joint>
  <link
    name="link_2">
    <inertial>
      <origin
        xyz="5.2117E-07 0.050183 0.046384"
        rpy="0 0 0" />
      <mass
        value="0.69106" />
      <inertia
        ixx="0.00048535"
        ixy="1.5042E-08"
        ixz="8.3749E-09"
        iyy="0.00052479"
        iyz="-4.8482E-05"
        izz="0.00040517" />
    </inertial>
    <visual>
      <origin
        xyz="0 0 0"
        rpy="0 0 0" />
      <geometry>
        <mesh
          filename="package://sunday_description/meshes/link_2.STL" />
      </geometry>
      <material
        name="">
        <color
          rgba="0.75294 0.75294 0.75294 1" />
      </material>
    </visual>
    <collision>
      <origin
        xyz="0 0 0"
        rpy="0 0 0" />
      <geometry>
        <mesh
          filename="package://sunday_description/meshes/link_2.STL" />
      </geometry>
    </collision>
  </link>
  <joint
    name="joint_2"
    type="revolute">
    <origin
      xyz="0 0.054512 0.049518"
      rpy="-0.0041482 0 0" />
    <parent
      link="link_1" />
    <child
      link="link_2" />
    <axis
      xyz="0 -0.99999 -0.0041482" />
    <limit
      lower="-1.54"
      upper="1.54"
      effort="30"
      velocity="3.14" />
  </joint>
  <link
    name="link_3">
    <inertial>
      <origin
        xyz="-2.3744E-06 0.013658 -0.095655"
        rpy="0 0 0" />
      <mass
        value="0.23037" />
      <inertia
        ixx="0.0001486"
        ixy="-3.2598E-10"
        ixz="-5.6218E-11"
        iyy="0.00014366"
        iyz="3.0147E-10"
        izz="7.1698E-05" />
    </inertial>
    <visual>
      <origin
        xyz="0 0 0"
        rpy="0 0 0" />
      <geometry>
        <mesh
          filename="package://sunday_description/meshes/link_3.STL" />
      </geometry>
      <material
        name="">
        <color
          rgba="0.79216 0.81961 0.93333 1" />
      </material>
    </visual>
    <collision>
      <origin
        xyz="0 0 0"
        rpy="0 0 0" />
      <geometry>
        <mesh
          filename="package://sunday_description/meshes/link_3.STL" />
      </geometry>
    </collision>
  </link>
  <joint
    name="joint_3"
    type="revolute">
    <origin
      xyz="0 -0.0008547 0.20604"
      rpy="-3.1374 0 0" />
    <parent
      link="link_2" />
    <child
      link="link_3" />
    <axis
      xyz="0 1 0" />
    <limit
      lower="-2.79"
      upper="2.79"
      effort="30"
      velocity="3.14" />
  </joint>
  <link
    name="link_4">
    <inertial>
      <origin
        xyz="-6.4344E-06 -0.026419 -0.014391"
        rpy="0 0 0" />
      <mass
        value="0.082188" />
      <inertia
        ixx="3.0297E-05"
        ixy="2.4262E-11"
        ixz="-2.0981E-10"
        iyy="3.1167E-05"
        iyz="-7.9506E-06"
        izz="2.8342E-05" />
    </inertial>
    <visual>
      <origin
        xyz="0 0 0"
        rpy="0 0 0" />
      <geometry>
        <mesh
          filename="package://sunday_description/meshes/link_4.STL" />
      </geometry>
      <material
        name="">
        <color
          rgba="0.79216 0.81961 0.93333 1" />
      </material>
    </visual>
    <collision>
      <origin
        xyz="0 0 0"
        rpy="0 0 0" />
      <geometry>
        <mesh
          filename="package://sunday_description/meshes/link_4.STL" />
      </geometry>
    </collision>
  </link>
  <joint
    name="joint_4"
    type="revolute">
    <origin
      xyz="0 -0.02136 -0.17442"
      rpy="0 0 0" />
    <parent
      link="link_3" />
    <child
      link="link_4" />
    <axis
      xyz="0 -1 0" />
    <limit
      lower="-2.79"
      upper="2.79"
      effort="30"
      velocity="3.14" />
  </joint>
  <link
    name="link_5">
    <inertial>
      <origin
        xyz="0.00020466 -0.017155 -0.036587"
        rpy="0 0 0" />
      <mass
        value="0.10205" />
      <inertia
        ixx="3.9776E-05"
        ixy="-5.7559E-07"
        ixz="-2.1528E-06"
        iyy="4.4113E-05"
        iyz="-9.1947E-06"
        izz="3.8817E-05" />
    </inertial>
    <visual>
      <origin
        xyz="0 0 0"
        rpy="0 0 0" />
      <geometry>
        <mesh
          filename="package://sunday_description/meshes/link_5.STL" />
      </geometry>
      <material
        name="">
        <color
          rgba="0 0 0 1" />
      </material>
    </visual>
    <collision>
      <origin
        xyz="0 0 0"
        rpy="0 0 0" />
      <geometry>
        <mesh
          filename="package://sunday_description/meshes/link_5.STL" />
      </geometry>
    </collision>
  </link>
  <joint
    name="joint_5"
    type="revolute">
    <origin
      xyz="0 -0.03573 -0.044358"
      rpy="0 0 0" />
    <parent
      link="link_4" />
    <child
      link="link_5" />
    <axis
      xyz="0 0 -1" />
    <limit
      lower="-2.79"
      upper="2.79"
      effort="30"
      velocity="3.14" />
  </joint>
  <link
    name="link_6">
    <inertial>
      <origin
        xyz="2.7756E-17 0 0"
        rpy="0 0 0" />
      <mass
        value="0.012566" />
      <inertia
        ixx="2.5133E-06"
        ixy="1.6577E-20"
        ixz="-3.3404E-20"
        iyy="1.3614E-06"
        iyz="-2.7021E-23"
        izz="1.3614E-06" />
    </inertial>
    <visual>
      <origin
        xyz="0 0 0"
        rpy="0 0 0" />
      <geometry>
        <mesh
          filename="package://sunday_description/meshes/link_6.STL" />
      </geometry>
      <material
        name="">
        <color
          rgba="1 0 0 1" />
      </material>
    </visual>
    <collision>
      <origin
        xyz="0 0 0"
        rpy="0 0 0" />
      <geometry>
        <mesh
          filename="package://sunday_description/meshes/link_6.STL" />
      </geometry>
    </collision>
  </link>
  <joint
    name="joint_6"
    type="revolute">
    <origin
      xyz="0 -0.099358 -0.03573"
      rpy="-1.5708 0 -1.5708" />
    <parent
      link="link_5" />
    <child
      link="link_6" />
    <axis
      xyz="1 0 0" />
    <limit
      lower="-2.79"
      upper="2.79"
      effort="30"
      velocity="3.14" />
  </joint>
  <link
    name="realsense">
    <inertial>
      <origin
        xyz="-0.0096916 -7.0438E-05 -0.0032432"
        rpy="0 0 0" />
      <mass
        value="0.10331" />
      <inertia
        ixx="7.3623E-05"
        ixy="2.0488E-08"
        ixz="-1.8002E-06"
        iyy="7.2833E-05"
        iyz="1.969E-08"
        izz="7.3133E-06" />
    </inertial>
    <visual>
      <origin
        xyz="0 0 0"
        rpy="0 0 0" />
      <geometry>
        <mesh
          filename="package://sunday_description/meshes/realsense.STL" />
      </geometry>
      <material
        name="">
        <color
          rgba="0.66667 0.69804 0.76863 1" />
      </material>
    </visual>
    <collision>
      <origin
        xyz="0 0 0"
        rpy="0 0 0" />
      <geometry>
        <mesh
          filename="package://sunday_description/meshes/realsense.STL" />
      </geometry>
    </collision>
  </link>
  <joint
    name="realsense_joint"
    type="fixed">
    <origin
      xyz="-0.00068847 -0.054242 -0.12654"
      rpy="-1.5708 0 -1.5708" />
    <parent
      link="link_5" />
    <child
      link="realsense" />
    <axis
      xyz="0 0 0" />
  </joint>





  
</robot>